<?xml version='1.0'?>
<sdf version='1.7'>
  <model name='subscale_model'>
  <pose> 0 0 0 0 0 1.57 </pose>
    <link name='fuselage'>
    <!--Clean up in future-->
      <inertial>
        <mass>0.001</mass>
        <inertia>
          <iyy>1000</iyy>
          <ixy>0.0</ixy>
          <ixx>9000</ixx>
          <ixz>0.0</ixz>
          <iyz>0.0</iyz>
          <izz>800</izz>
        </inertia>
        <pose>0.071 24.701 4.144 0 -0 0</pose>
      </inertial>
      <pose>0.010625 -0.006549 0 0 -0 0</pose>
     

      <visual name='visual'>
        <geometry>
          <mesh>
            <uri>/home/harish/Downloads/FCA-Simulation-main/Stls/Fuselage (1).stl</uri>
          </mesh>
        </geometry>
        <material>
          <lighting>1</lighting>
          <script>
            <uri>file://media/materials/scripts/gazebo.material</uri>
            <name>Gazebo/Blue</name>
          </script>
          </material>
      </visual>
      
            <visual name="cp_left_wing">
        <pose>-27 18 16 0 0 0</pose>
        <geometry>
          <sphere><radius>1</radius></sphere>
        </geometry>
      </visual>
    
      <collision name='collision'>
        <geometry>
          <mesh>
            <uri>/home/harish/Downloads/FCA-Simulation-main/Stls/Fuselage (1).stl</uri>
            <scale>1 1 1</scale>
          </mesh>
        </geometry>
      </collision>     <iyy>1000</iyy>
          <ixy>0.0</ixy>
          <ixx>9000</ixx>
          <ixz>0.0</ixz>
          <iyz>0.0</iyz>
          <izz>800</izz>
    </link>
    
   
    <link name='left_wing'>      
      <inertial>
        <mass>30</mass>
        <inertia>
          <ixx>867</ixx>
          <ixy>-241</ixy>
          <ixz>485</ixz>
          <iyx>-241</iyx>
          <iyy>9025</iyy>
          <iyz>36</iyz>
          <izx>485</izx>
          <izy>36</izy>
          <izz>9810</izz>

        </inertia>
        <pose>-31.006 21.669 14.927  0 -0 0</pose>
      </inertial>
      <pose>-0.002431 0.000506 0 0 -0 0</pose>
      <visual name='visual'>
        <pose>0 0 0 0 -0 0</pose>
        <geometry>
          <mesh>
            <uri>/home/harish/Downloads/FCA-Simulation-main/Stls/Left Wing.stl</uri>
            <scale>1 1 1</scale>
          </mesh>
        </geometry>
        <material>
          <lighting>1</lighting>
          <script>
            <uri>file://media/materials/scripts/gazebo.material</uri>
            <name>Gazebo/Grey</name>
          </script>
          <shader type='pixel'/>
        </material>
        <transparency>0</transparency>     <iyy>1000</iyy>
          <ixy>0.0</ixy>
          <ixx>9000</ixx>
          <ixz>0.0</ixz>
          <iyz>0.0</iyz>
          <izz>800</izz>
        <cast_shadows>1</cast_shadows>
      </visual>
      <collision name='collision'>
        <laser_retro>0</laser_retro>
        <max_contacts>10</max_contacts>
        <pose>0 0 0 0 -0 0</pose>
        <geometry>
          <mesh>
            <uri>/home/harish/Downloads/FCA-Simulation-main/Stls/Left Wing.stl</uri>
            <scale>1 1 1</scale>
          </mesh>
        </geometry>
    
      </collision>
    </link>
     
     
   <link name='motor'>
    <inertial>
      <mass>80</mass>
      <inertia>
        <ixx>100</ixx>
        <ixy>0</ixy>
        <ixz>0</ixz>
        <iyy>100</iyy>
        <iyz>0</iyz>
        <izz>100</izz>
      </inertia>
      <pose>0 0 4.144 0 -0 0</pose>
    </inertial>
    <pose>0.010625 -0.006549 0 0 -0 0</pose>
  </link>
  
    
    <link name='right_wing'>
      <inertial>
        <mass>30</mass>
        <inertia>      
          <ixx>867</ixx>
          <ixy>241</ixy>
          <ixz>-485</ixz>
          <iyx>241</iyx>
          <iyy>9025</iyy>
          <iyz>36</iyz>
          <izx>-485</izx>
          <izy>36</izy>
          <izz>9810</izz>
        </inertia>
        <pose>31.006 21.669 14.927  0 -0 0</pose>
      </inertial>
      <pose>-0.009494 0.005806 0 0 -0 0</pose>
      <visual name='visual'>
        <pose>0 0 0 0 -0 0</pose>
        <geometry>
          <mesh>
            <uri>/home/harish/Downloads/FCA-Simulation-main/Stls/Right Wing.stl</uri>
            <scale>1 1 1</scale>
          </mesh>
        </geometry>
        <material>
          <lighting>1</lighting>
          <script>
            <uri>file://media/materials/scripts/gazebo.material</uri>
            <name>Gazebo/Grey</name>
          </script>
          <shader type='pixel'/>
        </material>
        <transparency>0</transparency>
        <cast_shadows>1</cast_shadows>
      </visual>
      <collision name='collision'>
        <laser_retro>0</laser_retro>
        <max_contacts>10</max_contacts>
        <pose>0 0 0 0 -0 0</pose>
        <geometry>
          <mesh>
            <uri>/home/harish/Downloads/FCA-Simulation-main/Stls/Right Wing.stl</uri>
            <scale>1 1 1</scale>
          </mesh>
        </geometry>
       
      </collision>
    </link>


   <link name='stabilizers'>
      <inertial>
        <mass>12</mass>
        <inertia>
          <ixx>17</ixx>
          <ixy>0</ixy>
          <ixz>0</ixz>
          <iyy>178</iyy>
          <iyz>-0.3</iyz>
          <iyz>0</iyz>
          <izy>-0.3</izy>
          <izz>173</izz>
        </inertia>
        <pose>0 65.213 9.393 0 -0 0</pose>
      </inertial>
      <pose>-0.007465 -0.001724 0 0 -0 0</pose>
      <visual name='visual'>
        <pose>0 0 0 0 -0 0</pose>
        <geometry>
          <mesh>
            <uri>/home/harish/Downloads/FCA-Simulation-main/Stls/Stabalizers.stl</uri>
            <scale>1 1 1</scale>
          </mesh>
        </geometry>
        <material>
          <lighting>1</lighting>
          <script>
            <uri>file://media/materials/scripts/gazebo.material</uri>
            <name>Gazebo/Grey</name>
          </script>
          <shader type='pixel'/>
        </material>
        <transparency>0</transparency>
        <cast_shadows>1</cast_shadows>
      </visual>
      <collision name='collision'>
        <laser_retro>0</laser_retro>
        <max_contacts>10</max_contacts>
        <pose>0 0 0 0 -0 0</pose>
        <geometry>
          <mesh>
            <uri>/home/harish/Downloads/FCA-Simulation-main/Stls/Stabalizers.stl</uri>
            <scale>1 1 1</scale>
          </mesh>
        </geometry>
      </collision>
    </link>
    
  <link name='right_aileron'>
      <inertial>
        <mass>2</mass>
        <inertia>
          <ixx>2.806</ixx>
          <ixy>-0.01</ixy>
          <ixz>-3.35</ixz>
          <iyx>-0.015</iyx>
          <iyy>64.45</iyy>
          <iyz>0.29</iyz>
          <izx>-3.35</izx>
          <izy>0.29</izy>
          <izz>66.62</izz>
          
        </inertia>
        <pose>50.177 32.298  15.251 0 -0 0</pose>
      </inertial>
      <pose>-0.000807 -0.000738 0 0 -0 0</pose>
      <visual name='visual'>
        <pose>0 0 0 0 -0 0</pose>
        <geometry>
          <mesh>
            <uri>/home/harish/Downloads/FCA-Simulation-main/Stls/Right Aileron.stl</uri>
            <scale>1 1 1</scale>
          </mesh>
        </geometry>
        <material>
          <lighting>1</lighting>
          <script>
            <uri>file://media/materials/scripts/gazebo.material</uri>
            <name>Gazebo/Grey</name>
          </script>
          <shader type='pixel'/>
        </material>
        <transparency>0</transparency>
        <cast_shadows>1</cast_shadows>
      </visual>
      <collision name='collision'>
        <laser_retro>0</laser_retro>
        <max_contacts>10</max_contacts>
        <pose>0 0 0 0 -0 0</pose>
        <geometry>
          <mesh>
            <uri>/home/harish/Downloads/FCA-Simulation-main/Stls/Right Aileron.stl</uri>
            <scale>1 1 1</scale>
          </mesh>
        </geometry>
       
      </collision>
    </link>
    
     <link name='left_aileron'>
      <inertial>
        <mass>2</mass>
        <inertia>
          <ixx>2.806</ixx>
          <ixy>0.01</ixy>
          <ixz>3.35</ixz>
          <iyx>0.015</iyx>
          <iyy>64.45</iyy>
          <iyz>0.29</iyz>
          <izx>3.35</izx>
          <izy>0.29</izy>
          <izz>66.62</izz>
          
        </inertia>
        <pose>-50.177 32.298  15.251 0 -0 0</pose>
      </inertial>
      <pose>0.001717 0.004642 0 0 -0 0</pose>
      <visual name='visual'>
        <pose>0 0 0 0 -0 0</pose>
        <geometry>
          <mesh>
            <uri>/home/harish/Downloads/FCA-Simulation-main/Stls/Left Aileron.stl</uri>
            <scale>1 1 1</scale>
          </mesh>
        </geometry>
        <material>
          <lighting>1</lighting>
          <script>
            <uri>file://media/materials/scripts/gazebo.material</uri>
            <name>Gazebo/Grey</name>
          </script>
          <shader type='pixel'/>
        </material>
        <transparency>0</transparency>
        <cast_shadows>1</cast_shadows>
      </visual>
      <collision name='collision'>
        <laser_retro>0</laser_retro>
        <max_contacts>10</max_contacts>
        <pose>0 0 0 0 -0 0</pose>
        <geometry>
          <mesh>
            <uri>/home/harish/Downloads/FCA-Simulation-main/Stls/Left Aileron.stl</uri>
            <scale>1 1 1</scale>
          </mesh>
        </geometry>
      </collision>
    </link>
    
     <link name='right_elevator'>
      <inertial>
        <mass>1</mass>
        <inertia>
          <ixx>1</ixx>
          <ixy>-0.24</ixy>
          <ixz>-0.001</ixz>
          <iyx>-0.24</iyx>
          <iyy>16.76</iyy>
          <iyz>-0.007</iyz>
          <izx>-0.0017</izx>
          <izy>-0.007</izy>
          <izz>17.78</izz>
        </inertia>
        <pose>10.7 70.77 8.213 0 -0 0</pose>
      </inertial>
      <pose>-0.005405 -0.001289 0 0 -0 0</pose>
      <visual name='visual'>
        <pose>0 0 0 0 -0 0</pose>
        <geometry>
          <mesh>
            <uri>/home/harish/Downloads/FCA-Simulation-main/Stls/Right Elevator.stl</uri>
            <scale>1 1 1</scale>
          </mesh>
        </geometry>
        <material>
          <lighting>1</lighting>
          <script>
            <uri>file://media/materials/scripts/gazebo.material</uri>
            <name>Gazebo/Grey</name>
          </script>
          <shader type='pixel'/>
        </material>
        <transparency>0</transparency>
        <cast_shadows>1</cast_shadows>
      </visual>
      <collision name='collision'>
        <laser_retro>0</laser_retro>
        <max_contacts>10</max_contacts>
        <pose>0 0 0 0 -0 0</pose>
        <geometry>
          <mesh>
            <uri>/home/harish/Downloads/FCA-Simulation-main/Stls/Right Elevator.stl</uri>
            <scale>1 1 1</scale>
          </mesh>
        </geometry>
      </collision>
    </link>

 
    <link name='left_elevator'>
      <inertial>
        <mass>1</mass>
        <inertia>
          <ixx>1</ixx>
          <ixy>0.24</ixy>
          <ixz>0.001</ixz>
          <iyx>0.24</iyx>
          <iyy>16.76</iyy>
          <iyz>-0.007</iyz>
          <izx>0.0017</izx>
          <izy>-0.007</izy>
          <izz>17.78</izz>
        </inertia>
        <pose>-10.7 70.77 8.213 0 -0 0</pose>
      </inertial>
      <pose>-0.011106 0.004567 0 0 -0 0</pose>
      <visual name='visual'>
        <pose>0 0 0 0 -0 0</pose>
        <geometry>
          <mesh>
            <uri>/home/harish/Downloads/FCA-Simulation-main/Stls/Left Elevator.stl</uri>
            <scale>1 1 1</scale>
          </mesh>
        </geometry>
        <material>
          <lighting>1</lighting>
          <script>
            <uri>file://media/materials/scripts/gazebo.material</uri>
            <name>Gazebo/Grey</name>
          </script>
          <shader type='pixel'/>
        </material>
        <transparency>0</transparency>
        <cast_shadows>1</cast_shadows>
      </visual>
      <collision name='collision'>
        <laser_retro>0</laser_retro>
        <max_contacts>10</max_contacts>
        <pose>0 0 0 0 -0 0</pose>
        <geometry>
          <mesh>
            <uri>/home/harish/Downloads/FCA-Simulation-main/Stls/Left Elevator.stl</uri>
            <scale>1 1 1</scale>
          </mesh>
        </geometry>
      </collision>
    </link>


    <joint name = 'body3' type = 'fixed'>
    	<parent>fuselage</parent>
    	<child>right_wing</child>
    </joint>gazeb


    <joint name = 'body4' type = 'fixed'>
    	<parent>fuselage</parent>
    	<child>left_wing</child>
    </joint>


    <joint name = 'body5' type = 'fixed'>
    	<parent>fuselage</parent>
    	<child>stabilizers</child>
    </joint>

    <!--Joint for Right Aileron-->
    <joint name='right_aileron_joint' type = 'revolute'>
      <parent>right_wing</parent>
      <child>right_aileron</child>
      <pose>50 31 14.8 0 -0.052 0</pose> <!--TODO-->
      <axis>
        <xyz>1 0 0</xyz>
        <limit>
          <lower>-0.261667</lower>
          <upper>0.349066</upper>
          <velocity>0.61</velocity>
          <effort>1</effort>
        </limit>
      </axis>
    </joint>

    
    <!--Joint for Left Aileron-->
    <joint name='left_aileron_joint' type = 'revolute'>
      <parent>left_wing</parent>
      <child>left_aileron</child>
      <pose>-50 31 14.8 0 0.052 0</pose> <!--TODO-->
      <axis>
        <xyz>1 0 0</xyz>
        <limit>
          <lower>-0.261667</lower>
          <upper>0.349066</upper>
          <velocity>0.61</velocity> <!--Max velocity/effort? Also is effort similar to torqe or-->
          <effort>1</effort>
        </limit>
      </axis>
    </joint>

 <!--Joint for Right Elevator-->
    <joint name='left_elevator_joint' type = 'revolute'>
      <parent>stabilizers</parent>
      <child>left_elevator</child>
      <pose>-20 68.7 8.2 0 -0 0</pose> <!--TODO-where's the joint gonna be -->
      <axis>
        <xyz>1 0 0</xyz>
        <limit>
          <lower>-0.261667</lower>
          <upper>0.349066</upper>
          <velocity>0.61</velocity>
          <effort>1</effort>
        </limit>
      </axis>
    </joint>
    
       <link name='rudder'>
      <inertial>
        <mass>1</mass>
        <inertia>
          <ixx>13</ixx>      
          <iyy>11</iyy>
          <iyz>-0.12</iyz>
          <izy>-0.12</izy>
          <izz>1.81</izz>
        </inertia>
        <pose>0 71.795 11.808 0 -0 0</pose>
      </inertial>
      <pose>0.015142 -0.00431 0 0 -0 0</pose>
      <visual name='visual'>
        <pose>0 0 0 0 -0 0</pose>
        <geometry>
          <mesh>
            <uri>/home/harish/Downloads/FCA-Simulation-main/Stls/Rudder.stl</uri>
            <scale>1 1 1</scale>
          </mesh>
        </geometry>
        <material>
          <lighting>1</lighting>
          <script>
            <uri>file://media/materials/scripts/gazebo.material</uri>
            <name>Gazebo/Grey</name>
          </script>
          <shader type='pixel'/>
        </material>
        <transparency>0</transparency>00
        <cast_shadows>1</cast_shadows>
      </visual>
      <collision name='collision'>
        <laser_retro>0</laser_retro>
        <max_contacts>10</max_contacts>
        <pose>0 0 0 0 -0 0</pose>
        <geometry>
          <mesh>
            <uri>/home/harish/Downloads/FCA-Simulation-main/Stls/Rudder.stl</uri>
            <scale>1 1 1</scale>
          </mesh>
        </geometry>
       
      </collision>
    </link>
   <!--Joint for Right Elevator-->
    <joint name='right_elevator_joint' type = 'revolute'>
      <parent>stabilizers</parent>
      <child>right_elevator</child>
      <pose>20 68.7 8.2 0 -0 0</pose> <!--TODO-->
      <axis>00
        <xyz>1 0 0</xyz>
        <limit>
          <lower>-0.261667</lower>00
          <upper>0.349066</upper>
          <velocity>0.61</velocity>
          <effort>1</effort>
        </limit>
      </axis>
    </joint>

    <!--Joint for Rudder-->
    <joint name='rudder_joint' type = 'revolute'>
      <parent>stabilizers</parent>
      <child>rudder</child>
      <pose>0 69.1 19.3 0 -0 0</pose> <!--TODO-->
      <axis>
        <xyz>0 0 1</xyz>
        <limit>
          <lower>-0.35</lower>
          <upper>0.349066</upper>
          <velocity>0.61</velocity>
          <effort>1</effort>
        </limit>
      </axis>
    </joint>
    
    
        <joint name = 'motorjoint' type = 'fixed'>
    	<parent>fuselage</parent>
    	<child>motor</child>
    </joint>
    
    <static>0</static>
    <allow_auto_disable>1</allow_auto_disable>
  </model> 
</sdf>
